Workbook

Sheet Instructions
C3: Primary input
C4: Secondary input (only change under specific circumstances)
C5: Calculation - secondary or intermediate output
C6: Primary output "pass"
C7: Output "warning"
C8: Output "failure"

Sheet Design
P2: JIM MYERS & SONS | FK2: JIM MYERS & SONS
P3: SCREW CONVEYOR DESIGN SHEET | FK3: SCREW CONVEYOR DATA SHEET
P4: PROJECT NO.: | AG4: BY: | FK4: PROJECT: | GB4: BY:
P5: LOCATION: | AG5: DATE: | FK5: LOCATION: | GB5: DATE:
P6: CUSTOMER: | AG6: REVISION: | FK6: CUSTOMER: | GB6: REVISION:
P7: ENGINEER: | AG7: REV DATE: | FK7: ENGINEER: | GB7: REV DATE:
P8: DESCRIPTION: | AG8: PAGE: | AM8: OF | FK8: DESCRIPTION: | GB8: PAGE: | GH8: OF
B9: 1 | C9: CONVEYOR GENERAL INFORMATION | BC9: R | EW9: 1 | EX9: CONVEYOR GENERAL INFORMATION | GX9: REV
B10: 2 | C10: IDENTIFICATION: | AC10: CONVEYED MATERIAL: | EW10: 2 | EX10: IDENTIFICATION: | FX10: CONVEYED MATERIAL:
B11: 3 | C11: DESCRIPTION: | AC11: DENSITY: | AP11: =Reference!CB1 -> #N/A | AS11: LB/FT3 | EW11: 3 | EX11: DESCRIPTION: | FX11: DENSITY:
B12: 4 | C12: JMS ASSEMBLY: | AC12: SOLIDS CONTENT: | AP12: =Reference!CC1 -> #N/A | AS12: % | EW12: 4 | EX12: LENGTH: | FX12: MOISTURE:
B13: 5 | C13: LENGTH: | S13: FT | T13: ( | U13: =P13*12 -> 0 | X13: IN | Y13: ) | AC13: FLOWABILITY: | AP13: =Reference!CE1 -> #N/A | EW13: 5 | EX13: DESIGN CAPACITY: | FX13: FLOWABILITY:
B14: 6 | C14: DRIVE ARRANGEMENT: | AC14: SIZE: | AP14: =Reference!CD1 -> #N/A | EW14: 6 | EX14: INCLINE: | FX14: SIZE:
B15: 7 | C15: FLOW DIRECTION: | AC15: ABRASIVENESS: | AP15: =Reference!CF1 -> #N/A | EW15: 7 | EX15: SCREW DIAMETER: | FX15: TEMPERATURE:
B16: 8 | C16: SERVICE DUTY: | AC16: MATERIAL TEMPERATURE RANGE: | AS16: °F | AU16: MIN/ | AZ16: °F | BA16: MAX | EW16: 8 | EX16: SCREW PITCH: | FX16: OTHER CHARACTERISTICS:
B17: 9 | C17: LIVE BOTTOM: | AC17: OTHER CHARACTERISTICS: | AP17: =Reference!CG1 -> #N/A | EW17: 9 | EX17: DRIVE ARRANGEMENT: | FX17: NOTES:
B18: 10 | C18: AREA CLASSIFICATION: | AC18: NOTES: | AP18: -- | EW18: 10 | EX18: FLOW DIRECTION:
B19: 11 | C19: CAPACITY CALCULATIONS | AC19: POWER CALCULATIONS | EW19: 11 | EX19: SERVICE DUTY:
B20: 12 | C20: DESIGN CAPACITY: | M20: FT3/HR | P20: ( | Q20: =J20*AP11 -> #N/A | U20: LB/HR | W20: ) | AC20: GEARBOX: | EW20: 12 | EX20: LIVE BOTTOM:
B21: 13 | C21: SCREW DIAMETER: | M21: IN | AC21: SPEED: | AU21: :1 | AW21: RATIO | EW21: 13 | EX21: PROCESS CALCULATIONS
B22: 14 | C22: SCREW PITCH: | J22: Full | N22: ( | O22: =IF(J22="Full",J21,IF(J22="Short",(J21*(2/3)),IF(J22="Half",(J21/2),(J21*1.5)))) -> 0 | R22: IN | S22: ) | AC22: GEARBOX OUTPUT: | AW22: INCH SHAFT | EX22: Calculate the speed and power
B23: 15 | C23: SCREW TYPE: | AC23: MOUNTING: | AW23: ORIENTATION | EX23: requirements for the screw conveyor
B24: 16 | C24: SCREW PIPE SHAFT: | J24: None | R24: ="Standard = "&Reference!J3 -> #N/A | AC24: MOTOR: | EX24: based on design conditions.
B25: 17 | C25: SPIRAL SIZE: | R25: ="Standard = "&Reference!I2 -> #N/A | AC25: POWER: | AQ25: HP
B26: 18 | C26: TROUGH FILL: | M26: % | R26: % MAX | U26: Standard Max = 1.5X Design | AC26: GEARBOX SF: | AQ26: BASED ON NAMEPLATE HP
B27: 19 | C27: INCLINE: | M27: ° | AC27: EXPLOSION RATING: | EX27: CAPACITY CALCULATION TERMS
B28: 20 | AC28: DESIGN: | EX28: C | EZ28: = | FA28: Capacity
B29: 21 | AC29: DRIVE NOTES:
B30: 22 | C30: Ds | F30: = | G30: Screw Outside Diameter | O30: = | P30: =J21 -> 0 | T30: IN | AC30: L | AE30: = | AG30: Length | AN30: = | AO30: =P13 -> 0 | AR30: FT | EX30: N | EZ30: = | FA30: Conveyor Speed
B31: 23 | C31: Dp | F31: = | G31: Screw Inside Diameter | O31: = | P31: =Reference!H2 -> #N/A | T31: IN | AC31: N | AE31: = | AG31: Conveyor Speed | AN31: = | AO31: =P42 -> #N/A | AR31: RPM | EX31: Ds | EZ31: = | FA31: Screw Outside Diameter
B32: 24 | C32: P | F32: = | G32: Screw Pitch | O32: = | P32: =O22 -> 0 | T32: IN | AC32: Lh | AE32: = | AG32: Lift Height | AN32: = | AO32: =(SIN(RADIANS(J27)))*P13 -> 0 | AR32: FT | EX32: Dp | EZ32: = | FA32: Screw Inside Diameter
B33: 25 | C33: K | F33: = | G33: Trough Loading | O33: = | P33: =J26 -> 0 | T33: % | AC33: Fd | AE33: = | AG33: HP Factor | AN33: = | AO33: =VLOOKUP(J21,Reference!AJ5:AK30,2,FALSE) -> #N/A | EX33: P | EZ33: = | FA33: Screw Pitch
B34: 26 | C34: C1 | F34: = | G34: Mass Flow Factor | O34: = | P34: =IF(J23="Single Shaftless","1.1",IF(J23="Dual Shaftless","1.1","1.0")) -> 1.0 | AC34: Fb | AE34: = | AG34: Bearing Factor | AN34: = | AO34: =IF(AA82="","1",VLOOKUP(AA82,Reference!AM5:AN30,2,FALSE)) -> 1 | EX34: K | EZ34: = | FA34: Trough Loading
B35: 27 | C35: CF1 | F35: = | G35: Pitch Factor | O35: = | P35: 1 | AC35: Dm | AE35: = | AG35: Density of Material | AN35: = | AO35: =AP11 -> #N/A | AR35: LB/FT3 | EX35: C1 | EZ35: = | FA35: Mass Flow Factor
B36: 28 | C36: CF2 | D36: =IF(J26<16,"CF15_",IF(J26<31,"CF30_","CF45_")) -> CF15_ | F36: = | G36: Flight Factor | O36: = | P36: =INDEX(Reference!AA6:AC15,MATCH(Design!J23,Reference!Z6:Z15,0),MATCH(Design!D36,Reference!AA5:AC5,0)) -> #N/A | AC36: Fm | AE36: = | AG36: Material Factor | AN36: = | AO36: =VLOOKUP(AP10,Reference!AP5:AQ30,2,FALSE) -> #N/A | EX36: CF1 | EZ36: = | FA36: Pitch Factor
B37: 29 | C37: CF3 | D37: =IF(J23="Paddle 1x",1,IF(J23="Paddle 2x",2,IF(J23="Paddle 3x",3,IF(J23="Paddle 4x",4,"None")))) -> None | F37: = | G37: Mixing Factor | O37: = | P37: =VLOOKUP(D37,Reference!AE6:AF10,2,FALSE) -> 1 | AC37: Ff | AE37: = | AG37: Flight Mod HP Factor | AN37: = | AO37: 1 | EX37: CF2 | EZ37: = | FA37: Flight Factor
B38: 30 | C38: Ri | F38: = | G38: Incline Factor | O38: = | P38: =Reference!BB1 -> 1 | AC38: Fp | AE38: = | AG38: Paddle HP Factor | AN38: = | AO38: 1 | EX38: CF3 | EZ38: = | FA38: Mixing Factor
B39: 31 | C39: Cr | F39: = | G39: Required Capacity | O39: = | P39: =J20 -> 0 | T39: FT3/HR | AC39: Fo | AD39: =AO42+AO43 -> #N/A | AE39: = | AG39: Overload HP Factor | AN39: = | AO39: =IF(AD39<5.2,(LN(AD39)*-0.6115+2.024),1) -> #N/A | EX39: Cr | EZ39: = | FA39: Required Capacity
B40: 32 | C40: Ceq | F40: = | G40: Equivalent Capacity | O40: = | P40: =P39*P35*P36*P37 -> #N/A | T40: FT3/HR | AC40: FoMax | AD40: =AO42+AV43 -> #N/A | AE40: = | AG40: FO at Max Fill | AN40: = | AO40: =IF(AD40<5.2,(LN(AD40)*-0.6115+2.024),1) -> #N/A | EX40: Ceq | EZ40: = | FA40: Equivalent Capacity
B41: 33 | C41: Cr/N | F41: = | G41: Capacity per Rotation | O41: = | P41: =(0.7854*(P30^2-P31^2)*(P33/100)*P32*60*P34*P38)/1728 -> #N/A | T41: FT3/HR/RPM | AC41: e | AE41: = | AG41: Drive Efficiency | AN41: = | AO41: =Reference!EP1 -> #N/A | EX41: Cr/N | EZ41: = | FA41: Capacity per Rotation
...

Sheet Data Sheet
O2: JIM MYERS & SONS
O3: SCREW CONVEYOR DATA SHEET
O4: PROJECT NO.: | T4: =Design!U4 -> 0 | AF4: BY: | AJ4: =Design!AK4 -> 0
O5: LOCATION: | T5: =Design!U5 -> 0 | AF5: DATE: | AJ5: =Design!AK5 -> 0
O6: CUSTOMER: | T6: =Design!U6 -> 0 | AF6: REVISION: | AJ6: =Design!AK6 -> 0
O7: ENGINEER: | T7: =Design!U8 -> 0 | AF7: REV DATE: | AJ7: =Design!AK7 -> 0
O8: DESCRIPTION: | AF8: PAGE: | AJ8: =Design!AK8 -> 0 | AL8: OF | AM8: =Design!AN8 -> 0
A9: 1 | B9: CONVEYOR GENERAL INFORMATION | BB9: R
A10: 2 | B10: IDENTIFICATION: | O10: =Design!P10 -> 0 | AB10: FLOW DIRECTION: | AO10: =Design!P15 -> 0
A11: 3 | B11: DESCRIPTION: | O11: =Design!P11 -> 0 | AB11: SERVICE DUTY: | AO11: =Design!P16 -> 0
A12: 4 | B12: JMS ASSEMBLY: | O12: =Design!P12 -> 0 | AB12: LIVE BOTTOM: | AO12: =Design!P17 -> 0
A13: 5 | B13: LENGTH: | O13: =Design!P13&" FT" -> FT | T13: ="( "&Design!U13&" IN )" -> ( 0 IN ) | AB13: AREA CLASSIFICATION: | AO13: =Design!P18 -> 0
A14: 6 | B14: DRIVE ARRANGEMENT: | O14: =Design!P14 -> 0 | AB14: CONVEYED MATERIAL: | AO14: =Design!AP10 -> 0
A15: 7 | B15: CAPACITY: | O15: =Design!P43&" FT3/HR" -> #N/A | T15: ="("&Design!W43&" LB/HR )" -> #N/A | AB15: DENSITY: | AO15: =Design!AP11&" LB/FT3" -> #N/A
A16: 8 | B16: SPEED: | O16: =ROUND(Design!AO31,2)&" RPM DESIGN CAPACITY" -> #N/A | AB16: SOLIDS CONTENT: | AO16: =Design!AP12&" %" -> #N/A
A17: 9 | B17: DRIVE MODEL: | O17: =Design!AJ20&" "&Design!AQ20&" " | AB17: FLOWABILITY: | AO17: =Design!AP13 -> #N/A
A18: 10 | B18: DRIVE DETAILS: | O18: =Design!AJ21&" RPM / "&Design!AQ21&":1 RATIO" -> RPM / :1 RATIO | AB18: SIZE: | AO18: =Design!AP14 -> #N/A
A19: 11 | B19: DRIVE MOUNTING: | O19: =Design!AJ22&" Ø"&Design!AQ22&""" / "&Design!AJ23&" / "&Design!AQ23 -> Ø" / / | AB19: ABRASIVENESS: | AO19: =Design!AP15 -> #N/A
A20: 12 | B20: MOTOR: | O20: =Design!AJ24&" "&Design!AQ24&" / "&Design!AJ25&" HP" -> / HP | AB20: TEMPERATURE: | AO20: =Design!AP16&"°F MIN / "&Design!AW16&"°F MAX" -> °F MIN / °F MAX
A21: 13 | B21: NOTES: | O21: =Design!AJ28&" / "&Design!AJ29&" / EXPLOSION PROOF: "&Design!AJ27 -> / / EXPLOSION PROOF: | AB21: OTHER CHARACTERISTICS: | AO21: =Design!AP17 -> #N/A
A22: 14 | AB22: NOTES: | AO22: =Design!AP18 -> --
A23: 15
A24: 16
A25: 17
A26: 18 | B26: DESIGN INFORMATION
A27: 19 | B27: COMPONENT | J27: DETAIL | R27: SIZE | Z27: MATERIAL | AH27: QUANTITY | AP27: ADDITIONAL INFO
A28: 20 | B28: FLIGHT | J28: =Design!K78 -> 0 | R28: =Design!S78 -> 0 | Z28: =Design!AA78 -> 0 | AH28: -- | AP28: =Design!AQ78 -> --
A29: 21 | B29: PIPE SHAFT | J29: =IF(Reference!P2="Y","None","Yes") -> Yes | R29: =Design!J24 -> None | Z29: =Design!J53 -> None | AH29: 1 | AP29: --
A30: 22 | B30: SCREW CONNECTION | J30: =Design!J49 -> Flange | R30: =Design!J52 -> None | Z30: =Design!J53 -> None | AH30: -- | AP30: --
A31: 23 | B31: DRIVE END SHAFT | J31: Yes | R31: =Design!J50&"""" -> 2.438" | Z31: =Design!J51 -> 1045 CS | AH31: 1 | AP31: =IF(J30="Flange","--",Design!J56&"X Ø"&TEXT(Design!T72,"# #/##")&""" HOLES") -> --
A32: 24 | B32: COUPLING SHAFT | J32: =IF(Design!T96>0,"Yes","No") -> Yes | R32: =IF(J32="Yes",Design!T65&"""","--") -> 2.438" | Z32: =IF(J32="Yes",Design!J51,"No") -> 1045 CS | AH32: =IF(J32="Yes",Design!T96,"--") -> -- | AP32: =IF(J32="Yes",IF(J30="Flange","--",Design!J56&"X Ø"&TEXT(Design!T72,"# #/##")&""" HOLES EACH END"),"--") -> --
A33: 25 | B33: TAIL END SHAFT | J33: =IF(J28="Shafted","Yes","No") -> No | R33: =IF(J33="Yes",Design!J50&"""","--") -> -- | Z33: =IF(J33="Yes",Design!J51,"--") -> -- | AH33: =IF(J33="Yes","1","--") -> -- | AP33: =IF(J30="Flange","--",Design!J56&"X Ø"&TEXT(Design!T72,"# #/##")&""" HOLES") -> --
A34: 26 | B34: DRIVE END COUPLING | J34: =IF(Design!K90="None","No",Design!K90) -> 0 | R34: =IF(J34="No","--",Design!S90) -> 0 | Z34: =IF(J34="No","--",Design!AA90) -> 0 | AH34: =IF(J34="No","--","1") -> 1 | AP34: =IF(J34="No","--",Design!AQ90) -> 0
A35: 27 | B35: DRIVE END SEAL | J35: =IF(Design!K79="None","No",Design!K78) -> 0 | R35: =IF(J35="No","--",Design!S79) -> 2.438" | Z35: =IF(J35="No","--",Design!AA79) -> 0 | AH35: =IF(J35="No","--",Design!AI79) -> -- | AP35: =IF(J35="No","--",Design!AQ79) -> 0
A36: 28 | B36: TAIL END SEAL | J36: =IF(Design!K80="None","No",Design!K80) -> 0 | R36: =IF(J36="No","--",Design!S80) -> 2.438" | Z36: =IF(J36="No","--",Design!AA80) -> 0 | AH36: =IF(J36="No","--",Design!AI80) -> -- | AP36: =IF(J36="No","--",Design!AQ80) -> 0
A37: 29 | B37: DRIVE END BEARING | J37: =IF(Design!K81="None","No",Design!K81) -> 0 | R37: =IF(J37="No","--",Design!S81) -> 2.438" | Z37: =IF(J37="No","--",Design!AA81) -> 0 | AH37: =IF(J37="No","--",Design!AI81) -> -- | AP37: =IF(J37="No","--",Design!AQ81) -> 0
A38: 30 | B38: HANGER BEARING | J38: =IF(Design!K82="None","No",Design!K82) -> 0 | R38: =IF(J38="No","--",Design!T65&"""") -> 2.438" | Z38: =IF(J38="No","--",Design!AA82) -> 0 | AH38: =IF(J38="No","--",Design!AI82) -> -- | AP38: =IF(J38="No","--",Design!AQ82) -> 0
A39: 31 | B39: TAIL END BEARING | J39: =IF(Design!K83="None","No",Design!K83) -> 0 | R39: =IF(J39="No","--",Design!S83) -> 2.438" | Z39: =IF(J39="No","--",Design!AA83) -> 0 | AH39: =IF(J39="No","--",1) -> 1 | AP39: =IF(J39="No","--",Design!AQ83) -> 0
A40: 32 | B40: TROUGH | J40: =Design!K84 -> 0 | R40: =IF(ISBLANK(Design!S84),"--",Design!S84) -> 10 ga | Z40: =IF(ISBLANK(Design!AA84),"--",Design!AA84) -> -- | AH40: =IF(ISBLANK(Design!AI84),"--",Design!AI84) -> -- | AP40: =IF(ISBLANK(Design!AQ84),"--",Design!AQ84) -> --
A41: 33 | B41: COVER | J41: =Design!K85 -> 0 | R41: =IF(ISBLANK(Design!S85),"--",Design!S85) -> 12 ga | Z41: =IF(ISBLANK(Design!AA85),"--",Design!AA85) -> -- | AH41: =IF(ISBLANK(Design!AI85),"--",Design!AI85) -> -- | AP41: =IF(ISBLANK(Design!AQ85),"--",Design!AQ85) -> --
...

Sheet Report
P2: JIM MYERS & SONS
P3: SCREW CONVEYOR DATA SHEET
P4: PROJECT: | AG4: BY:
P5: LOCATION: | AG5: DATE:
P6: CUSTOMER: | AG6: REVISION:
P7: ENGINEER: | AG7: REV DATE:
P8: DESCRIPTION: | AG8: PAGE: | AM8: OF
B9: 1 | C9: CONVEYOR GENERAL INFORMATION | BC9: REV
B10: 2
B11: 3

Sheet Screw Thrust Calculator
A1: Screw Conveyor Thrust Calculator
A2: CONVEYOR APPLICATION DATA
A3: Motor HP | B3: =Design!AJ25 -> 0 | C3: hp
A4: Drive RPM | B4: =Design!AJ21 -> 0 | C4: rpm
A5: Screw Outside Diameter (Inches) | B5: =Design!J21 -> 0 | C5: in
A6: Screw Inside Diameter (Inches) | B6: =Design!P31 -> #N/A | C6: in
A7: Screw Pitch (Inches) | B7: =Design!O22 -> 0 | C7: in
A9: INPUTS
A10: Torque (Mt) | B10: =(B3*63025)/B4 -> #DIV/0! | C10: lb-in
A11: Mean Diameter (Dm) | B11: =(B5+B6)/2 -> #N/A | C11: in
A12: Coefficient of Friction (µ) | B12: =VLOOKUP(Design!AP10,Reference!ES4:ET13,2,FALSE) -> #N/A | C12: µ | D12: VERIFY IN TABLE TO THE RIGHT
A14: CALCULATIONS
A15: Helix Angle (α) | B15: =DEGREES((B7)/(PI()*B5)) -> #DIV/0! | C15: degrees
A16: Friction Angle (ρ) | B16: =DEGREES(ATAN(B12)) -> #N/A | C16: degrees
A17: Axial Thrust (Fa) | B17: =(B10/(B11/2))*TAN(RADIANS(B15+B16)) -> #DIV/0! | C17: lbf
A19: EQUATIONS USED
A20: Fa = (Mt / (Dm / 2)) * tan(α + ρ)
A21: ρ = arctan(µ)

Sheet Seismic
P2: JIM MYERS & SONS
P3: CALCULATION SHEET
P4: PROJECT NO.: | U4: =Design!U4 -> 0 | AG4: BY: | AK4: =Design!AK4 -> 0
P5: LOCATION: | U5: =Design!U5 -> 0 | AG5: DATE: | AK5: =Design!AK5 -> 0
P6: CUSTOMER: | U6: =Design!U6 -> 0 | AG6: REVISION: | AK6: =Design!AK6 -> 0
P7: ENGINEER: | U7: =Design!U7 -> 0 | AG7: REV DATE: | AK7: =Design!AK7 -> 0
P8: DESCRIPTION: | U8: =Design!U8 -> 0 | AG8: PAGE: | AK8: 1 | AM8: OF | AN8: 1
B9: 1 | C9: CONVEYOR SUPPORT STRUCTURE SEISMIC | BC9: R
B10: 2 | C10: R | D10: = | E10: 3 | H10: Ref ASCE/SEI 7-10 Table 13.6-1 | AC10: Risk Category: II
B11: 3 | C11: ap | D11: = | E11: 2.5 | H11: Ref ASCE/SEI 7-10 Table 13.6-1 | AC11: Site Soil Class: D - Default
B12: 4 | C12: Ip | D12: = | E12: 1.5 | H12: Ref ASCE/SEI 7-10 Section 13.1.3 Component Importance Factor | AC12: ASCE/SEI 7-16
B13: 5 | C13: SDS | D13: = | E13: 0.5 | H13: Use ASCE 7 Hazard Tool | O13: https://asce7hazardtool.online/
B14: 6
B15: 7 | C15: Vx | D15: = | E15: =((0.4*E11*E13)/(E10/E12))*3 -> 0.75
B16: 8 | C16: VZ | D16: = | E16: =((0.4*E11*E13)/(E10/E12))*3 -> 0.75
B17: 9
B18: 10
B19: 11
B20: 12 | C20: JMS CALCULATION SHEET REV. 0

Sheet List
A2: Boolean | B2: TYPE | C2: SCREW SIZE | D2: Drive Mounting | E2: Duty | F2: Explosion | K2: Flow | L2: Material | M2: Size | N2: Flowability | O2: Abrasiveness | P2: Other Properties | Q2: Pitch | R2: Spiral Type | S2: Pipe | U2: Gearbox | V2: Motor | W2: HP | X2: Output | Y2: Mounting | Z2: Position | AA2: GB Shaft | AB2: Motor Design | AC2: Connection | AD2: Drive Shaft | AE2: Coupling Bolt | AG2: Bolt Pad | AH2: Flight T | AI2: Flight W | AJ2: Trough T | AK2: Cover T | AL2: Liner | AM2: Liner T | AN2: Shaft Bearing | AO2: Bearing PN | AP2: Housing Material | AQ2: Hanger Style | AR2: Hanger Bearing | AS2: Housing Material | AT2: Seal | AU2: Housing Material | AV2: Shaft Material | AW2: Pipe Material | AX2: Flight Material | AY2: Bolt Material | AZ2: Trough | BA2: Trough Material | BB2: Cover | BC2: Cover Material | BD2: Clamp | BE2: Inlet | BF2: Outlet | BG2: COUPLING | BH2: ZSS | BI2: ESTOP | BJ2: Housing
A3: Yes | B3: Shafted | C3: 6 | D3: Direct Coupled In-line | E3: Light | F3: NO | K3: Push | L3: Wet Sludge | M3: Very Fine | N3: Very Free Flowing | O3: Mild | P3: Build Up / Harden | Q3: Full | R3: Shafted | S3: None | U3: F57 | V3: DRN80M4 | W3: 1 | X3: Hollow Bore | Y3: B5 Flange | Z3: M1 | AA3: 1 | AB3: Not Specified | AC3: Cross-Bolt Coupling | AD3: 1 | AE3: None | AF3: 0 | AG3: None | AH3: 0.1875 | AI3: 1 | AJ3: 16 ga | AK3: 16 ga | AL3: None | AM3: None | AN3: None | AP3: None | AQ3: None | AR3: None | AS3: None | AT3: None | AU3: None | AV3: 1045 CS | AW3: None | AX3: Carbon Steel | AY3: None | AZ3: U | BA3: Carbon Steel | BB3: Flanged | BC3: Carbon Steel | BD3: C | BE3: None | BF3: None | BG3: None | BH3: No | BI3: No | BJ3: Aluminum
A4: No | B4: Shaftless | C4: 9 | D4: Screw Conveyor Drive | E4: Standard | F4: CLASS 1 DIV 1 | K4: Pull | L4: Wet Sludge + Lime | M4: Fine | N4: Free Flowing | O4: Moderate | P4: Generate Static Electricity | Q4: Short | R4: Single Shaftless | S4: 2" SCH 40 | U4: F57R37 | V4: DRN90S4 | W4: 1.5 | X4: Solid Shaft | Y4: B14 Flange | Z4: M1A | AA4: 1.188 | AB4: NEMA A | AC4: Flange | AD4: 1.188 | AE4: 0.375 | AF4: 1 | AG4: 0.25 | AH4: 0.25 | AI4: 1.75 | AJ4: 14 ga | AK4: 14 ga | AL4: UHMW | AM4: 1/4 | AN4: Flange Ball | AP4: Cast Iron | AQ4: 220 | AR4: Babbit | AS4: Cast Iron | AT4: Plate Seal | AU4: Cast Iron | AV4: 1018 CS | AW4: Carbon Steel | AX4: 304 SS | AY4: A307 | AZ4: Tube | BA4: 304 SS | BB4: Flat | BC4: 304 SS | BD4: Spring | BE4: Open | BF4: Open | BG4: Rigid | BH4: MSP 12 | BI4: RS2 | BJ4: Stainless Steel
C5: 10 | D5: Shaft Mount Drive | E5: Heavy | F5: CLASS 1 DIV 2 | K5: Reversing | L5: Partially Dried Sludge/Paste | M5: Granular | N5: Average | O5: Extreme | P5: Decomposes in Storage | Q5: Half | R5: Dual Shaftless | S5: 2" SCH 80 | U5: F67 | V5: DRN90L4 | W5: 2 | X5: CEMA 2-Hole | Y5: Foot | Z5: M1B | AA5: 1.25 | AB5: NEMA B | AD5: 1.25 | AE5: 0.5 | AF5: 2 | AG5: 0.375 | AH5: 0.375 | AI5: 2 | AJ5: 12 ga | AK5: 12 ga | AL5: UHMW 2 Color | AM5: 3/8 | AN5: Flange Roller | AP5: Carbon Steel | AQ5: 226 | AR5: Bronze | AS5: Carbon Steel | AT5: Waste Packing | AU5: Carbon Steel | AV5: 4140 Alloy | AW5: 304 SS | AX5: 316 SS | AY5: A325 | AZ5: Flared | BA5: 316 SS | BB5: Ridged | BC5: 316 SS | BD5: Toggle | BE5: Square Flange | BF5: Square Flange | BG5: Chain | BH5: SCP100 | BI5: RS2X | BJ5: Plastic
C6: 12 | D6: Gearbox with Chain & Sprocket | F6: CLASS 2 DIV 1 | L6: Dry Biosolids | M6: Lumpy | N6: Sluggish | P6: Flammability | Q6: Long | R6: Ribbon | S6: 2.5" SCH 40 | U6: F67R37 | V6: DRN100LM4 | W6: 3 | X6: CEMA 3-Hole | Y6: Torque Arm | Z6: M2 | AA6: 1.375 | AB6: NEMA C | AD6: 1.375 | AE6: 0.625 | AF6: 3 | AG6: 0.5 | AH6: 0.75" x 2.5" | AI6: 2.5 | AJ6: 10 ga | AK6: 10 ga | AM6: 1/2 | AN6: Flange Spherical | AP6: Stainless Steel | AQ6: 216 | AR6: Bronze with Graphite | AS6: Stainless Steel | AT6: Split Gland | AU6: Stainless Steel | AV6: 4140 Hardened | AW6: 316 SS | AX6: Alloy 8620 | AY6: 304 SS | AZ6: Other | BB6: Hinged | BD6: Bolted | BE6: Round Flange | BF6: Round Flange | BG6: Flexible | BI6: RS5
C7: 14 | D7: Gearbox with Belt & Sheave | F7: CLASS 2 DIV 2 | L7: Raw Screenings | M7: Irregular | P7: Becomes Plastic / Softens | R7: Cut | S7: 2.5" SCH 80 | U7: F77 | V7: DRN100L4 | W7: 5 | Z7: M3 | AA7: 1.438 | AD7: 1.438 | AE7: 0.75 | AH7: 1" x 3" | AI7: 3 | AJ7: 3/16 | AK7: 1/8 | AN7: Pillow Block Ball | AQ7: 70 | AR7: Ceramic | AT7: Flanged Gland | AU7: Aluminum | AV7: 304 SS | AW7: A53-77a | AX7: T1 | AY7: 316 SS | BB7: None | BD7: Hinged | BI7: RS5X
C8: 16 | D8: Open Spur Gear | L8: Compacted Screenings | P8: Very Dusty | R8: Cut & Folded | S8: 3" SCH 40 | U8: F77R37 | V8: DRN132S4 | W8: 7.5 | Z8: M4 | AA8: 1.5 | AD8: 1.5 | AE8: 0.875 | AH8: 1" x 4" | AI8: 3.5 | AJ8: 1/4 | AK8: 3/16 | AN8: Pillow Block Roller | AQ8: 19B | AR8: Graphite | AV8: 316 SS | AX8: AR400 | BD8: None
C9: 18 | L9: Submerged Grit | P9: Aerates / Becomes Fluid | R9: Paddle 1x | S9: 3" SCH 80 | U9: F87 | V9: DRN132M4 | W9: 10 | Z9: M4A | AA9: 1.938 | AD9: 1.938 | AE9: 1 | AH9: 0.75" x 2.5" / 0.5" X 1" | AI9: 4 | AJ9: 3/8 | AK9: 1/4 | AN9: Pillow Block Spherical | AR9: Hard Iron/Hardox | AV9: 17-4PH -A
C10: 20 | L10: Dewatered Grit | P10: Explosiveness | R10: Paddle 2x | S10: 3.5" SCH 40 | U10: F87R77 | V10: DRN132L4 | W10: 12.3 | Z10: M4B | AA10: 2 | AD10: 2 | AE10: 1.125 | AH10: 1" x 3" / 0.75" X 1.75" | AK10: 3/8 | AR10: Stellite | AV10: 17-4PH -H900
C11: 24 | L11: Lime Pebble | P11: Stickiness / Adhesive | R11: Paddle 3x | S11: 3.5" SCH 80 | U11: F97 | V11: DRN160M4 | W11: 15 | AA11: 2.375 | AD11: 2.375 | AE11: 1.25 | AH11: 1" x 3" / 0.75" X 2.5" | AR11: Plastech | AV11: 17-4PH -H1150
L12: Lime Powder/Hydrated | P12: Harmful / Toxic Gas or Fumes | R12: Paddle 4x | S12: 4" SCH 40 | U12: F97R57 | V12: DRN160L4 | W12: 20 | AA12: 2.438 | AD12: 2.438 | AH12: 1" x 4" / 0.75" X 3" | AR12: Nylon
L13: Other | P13: Highly Corrosive | S13: 4" SCH 80 | U13: F107 | V13: DRN180M4 | W13: 25 | AA13: 2.75 | AD13: 2.75 | AR13: Teflon
P14: Mildly Corrosive | S14: 5" SCH 40 | U14: F107R77 | V14: DRN180L4 | W14: 30 | AA14: 2.875 | AD14: 2.875 | AR14: UHMW
P15: Packs Under Pressure | S15: 5" SCH 80 | U15: F127 | AA15: 2.938 | AD15: 2.938
P16: Elevated Temperature | S16: 6" SCH 40 | U16: F127R87 | AA16: 3 | AD16: 3
P17: -- | S17: 6" SCH 80 | U17: F157 | AA17: 3.25 | AD17: 3.25
S18: 8" SCH 40 | U18: F157R97 | AA18: 3.438 | AD18: 3.438
S19: 8" SCH 80 | U19: K57 | AA19: 3.625 | AD19: 3.625
S20: 10" SCH 40 | U20: K67R37 | AA20: 3.75 | AD20: 3.75
S21: 10" SCH 80 | U21: K77 | AA21: 3.875 | AD21: 3.875
S22: 12" SCH 40 | U22: K77R37 | AA22: 4 | AD22: 4
S23: 12" SCH 80 | U23: K87 | AA23: 4.5 | AD23: 4.5 | AH23: 0.25
U24: K87R57 | AH24: 0.375
U25: K97 | AH25: 0.5
U26: K97R57 | AH26: 0.625
U27: K107 | AH27: 0.75
U28: K107R77 | AH28: 1
U29: K127
U30: K127R77
U31: K127R87
U32: K157
U33: K157R97
U34: K157R107
U35: K167
U36: K167R97
U37: K167R107

Sheet Reference
A1: SIZE | B1: STYLE | D1: DUTY | F1: PIPE | G1: PIPE ID | H1: ID | I1: FLIGHT | J1: SHAFT | K1: LB/FT | L1: BC | M1: bs | N1: hs | P1: Is Shaftless | Q1: Connection | R1: Bolt Pad | S1: EQ Pipe OD | V1: ALL LOOKUPS SEARCH THROUGH THE TABLES TO THE RANGE THAT HAVE BORDERS. | AY1: =IF(Design!J27<10,0,MROUND(Design!J27,5)) -> 0 | AZ1: =Design!J22 -> Full | BA1: =IF(P2="Y","Shaftless",AZ1) -> Full | BB1: =INDEX(AY4:BD13,MATCH(AY1,AY4:AY13,0),MATCH(BA1,AY4:BD4,0)) -> 1 | BF1: =Design!J50 -> 2.438 | BG1: =VLOOKUP(BF1,BF5:BG14,2,TRUE) -> 0.625 | BQ1: =Design!AA78 -> 0 | BR1: =VLOOKUP(BQ1,BQ5:BR14,2,) -> #N/A | CA1: =Design!AP10 -> 0 | CB1: =VLOOKUP($CA$1,$CA$5:$CH$15,2,FALSE) -> #N/A | CC1: =VLOOKUP($CA$1,$CA$5:$CH$15,3,FALSE) -> #N/A | CD1: =VLOOKUP($CA$1,$CA$5:$CH$15,4,FALSE) -> #N/A | CE1: =VLOOKUP($CA$1,$CA$5:$CH$15,5,FALSE) -> #N/A | CF1: =VLOOKUP($CA$1,$CA$5:$CH$15,6,FALSE) -> #N/A | CG1: =VLOOKUP($CA$1,$CA$5:$CH$15,7,FALSE) -> #N/A | CH1: =VLOOKUP($CA$1,$CA$5:$CH$15,8,FALSE) -> #N/A | DP1: =Design!J24 -> None | DQ1: =IF(DP1="None","-",VLOOKUP(DP1,DP4:DR30,2,FALSE)) -> - | DR1: =IF(DP1="None","-",VLOOKUP(DP1,DP4:DR30,3,FALSE)) -> - | DU1: SHAFT | DV1: =Design!J51 -> 1045 CS | DW1: FLIGHT | DX1: =Design!AA78 -> 0 | EC1: =Design!K86 -> 0 | ED1: =EE1&""" x "&EE1&""" Inside" -> #N/A | EE1: =VLOOKUP(A2,EC4:EE13,3,FALSE) -> #N/A | EF1: =Design!K87 -> 0 | EK1: =A2 -> 0 | EL1: =VLOOKUP(EK1,EK4:EL12,2,FALSE) -> #N/A | EO1: =Design!P14 -> 0 | EP1: =VLOOKUP(EO1,EO4:EP13,2,FALSE) -> #N/A
A2: =Design!J21 -> 0 | B2: =Design!J23 -> 0 | C2: =IF(B3="Dual",A3&B3,IF(B3="Single",A3&B3,A3&B3&D3)) -> Other3 | D2: =Design!P16 -> 0 | F2: =IF(Design!J24="None",Design!J52,Design!J24) -> None | G2: =VLOOKUP(F2,DP4:DR30,3,FALSE) -> #N/A | H2: =IF(B2="Shafted",F3,IF(B2="Single Shaftless",C3,IF(B2="Dual Shaftless",C3,F3))) -> #N/A | I2: =VLOOKUP(C2,A5:J49,7,FALSE) -> #N/A | J2: =VLOOKUP(C2,A5:J49,9,FALSE) -> #N/A | K2: =VLOOKUP(C2,A5:J49,8,FALSE) -> #N/A | L2: =VLOOKUP(C2,A5:L49,12,FALSE) -> #N/A | M2: =VLOOKUP($H$3,$G$5:$N$22,7,FALSE) -> #N/A | N2: =VLOOKUP($H$3,$G$5:$N$22,8,FALSE) -> #N/A | P2: =IF(B3="Dual","Y",IF(B3="Single","Y","N")) -> N | Q2: =IF(P2="Y","Flanged","Cross-Bolt Coupling") -> Cross-Bolt Coupling | R2: =IF(Design!J57="None",0,Design!J57) -> 0 | S2: =F3+(2*R2) -> #N/A | V2: CEMA Table 2-4 | CI2: =Design!AP11 -> #N/A | CJ2: =Design!AP14 -> #N/A | CK2: =VLOOKUP(CJ2,CJ5:CK20,2,FALSE) -> #N/A | CL2: =Design!AP13 -> #N/A | CM2: =VLOOKUP(CL2,CL5:CM20,2,FALSE) -> #N/A | CN2: =Design!AP15 -> #N/A | CO2: =VLOOKUP(CN2,CN5:CO20,2,FALSE) -> #N/A | CP2: =Design!AP17 -> #N/A | CQ2: =VLOOKUP(CP2,CP5:CQ20,2,FALSE) -> #N/A | DE2: Selected | DF2: List | DG2: Speeds | DI2: Ratio | DV2: =VLOOKUP(DV1,DU4:DY17,2,FALSE) -> 28000000 | DW2: =VLOOKUP(DX1,DU4:DY17,3,FALSE) -> #N/A | DX2: =VLOOKUP(DX1,DU4:DY17,2,FALSE) -> #N/A | EC2: =IF(EC1="Square Flange",ED1,IF(EC1="Round Flange",ED2,IF(EC1="None","--",ED1))) -> #N/A | ED2: ="Ø "&EE1&""" Inside" -> #N/A | EE2: =VLOOKUP(A2,EC4:EF13,4,FALSE) -> #N/A | EF2: =IF(EF1="Square Flange",ED1,IF(EF1="Round Flange",ED2,IF(EF1="None","--",ED1))) -> #N/A | EG2: =VLOOKUP(A2,EC4:EG13,4,FALSE) -> #N/A | EI2: Round
A3: =TEXT(A2,"##") | B3: =IF(B2="Shafted","Shafted",IF(B2="Single Shaftless","Single",IF(B2="Dual Shaftless","Dual","Other"))) -> Other | C3: =VLOOKUP(C2,A5:K22,11,FALSE) -> #N/A | D3: =IF(D2="Light","1",IF(D2="Standard","2","3")) -> 3 | F3: =VLOOKUP(F2,DP4:DR30,2,FALSE) -> #N/A | H3: =Design!J25 -> 0 | I3: =VLOOKUP(C2,A5:J49,3,FALSE) -> #N/A | J3: =VLOOKUP(C2,A5:J49,10,FALSE) -> #N/A | V3: Pitch Capacity Factor | Z3: Special Flight Capacity Factor. If not listed, use 1 | AE3: Special Mixing Paddle Capacity Factor | AJ3: Diameter HP Factor | AM3: Hanger Bearing HP Factor | AP3: Material Factor | AS3: Flight Modification HP Factor | AV3: Paddle HP Factor | AY3: Incline Factor | BF3: Standard Bolt Size | BG3: Bolt | BI3: Bolt Allowable Stress | BM3: Shaft Allowable Stress | BQ3: Flight Yield Stress | BU3: Coefficent of Thermal Expansion | BX3: Gauge Size | CA3: Standard Material Characteristics *these are average values | CJ3: Material Characteristics per CEMA | CN3: CODE = | CO3: =CI2&CK2&CM2&CO2&CQ2 -> #N/A | CV3: Ratios | CW3: Number | CX3: Lookup | CZ3: Ratio | DA3: Output RPM | DB3: Max Output Torque (in-lb) | DC3: Max Overhung Load (lbf) | DE3: =Design!AQ20 -> 0 | DH3: =Design!AJ21 -> 0 | DI3: =DE3&DH3 -> 00 | DL3: hp | DM3: Motor Model | DN3: RPM | DP3: Pipe Size | DQ3: OD | DR3: ID | DU3: Material Properties | DV3: E (psi) | DW3: Sy (psi) | DX3: Sult (psi) | DY3: Density (lb/in3) | EC3: Screw Diameter | EE3: Inside Width | EF3: CL to Trough End Min | EG3: H from CL | EI3: ID | EK3: Screw Diameter | EL3: Trough Length | EM3: Cover Length | EO3: Drive | EP3: Drive efficiency | ES3: Material Type | ET3: µ (approx.)
B4: ID | C4: OUTER T | D4: OUTER W | E4: INNER T | F4: INNER W | G4: SPIRALS | H4: WEIGHT PER FT | I4: STD SHAFT | J4: STD PIPE | K4: ID FROM FLIGHT | L4: FL BC | M4: SPIRAL THICKNESS AVG | N4: SPIRAL WIDTH | Z4: Type | AA4: CF2 | AB4: CF2 | AC4: CF2 | AE4: Paddles per Pitch set at 45deg reverse pitch | AJ4: Diameter | AK4: Fd | AM4: Type | AN4: Fb | AP4: Material | AQ4: Fm | AT4: Ff | AV4: Paddle Number | AW4: Fp | AY4: Incline | AZ4: Full | BA4: Short | BB4: Half | BC4: Long | BD4: Shaftless | BF4: Shaft | BG4: Bolt | BI4: Material | BJ4: Yield | BK4: Shear | BM4: Material | BN4: Yield | BO4: Shear | BQ4: Material | BR4: Yield | BU4: Material | BV4: CTE | BX4: GA | BY4: Thickness (in) | CA4: Material | CB4: Density lb/ft3 | CC4: Percent DS | CD4: Size | CE4: Flowability | CF4: Abrasiveness | CG4: Other Properties 1 | CH4: Other Properties 2 | CJ4: Size | CK4: Code | CL4: Flowability | CM4: Code | CN4: Abrasiveness | CO4: Rating | CP4: Other Properties | CV4: K57 | CW4: 1 | CX4: K57_1 | CY4: K5712 | CZ4: 145.14 | DA4: 12 | DB4: 5310 | DC4: 1720 | DE4: 1 | DF4: =$DE$3&"_"&DE4 -> 0_1 | DG4: =VLOOKUP(DF4,$CX$4:$DC$523,4,FALSE) -> #N/A | DH4: =$DE$3&DG4 -> #N/A | DI4: =VLOOKUP($DI$3,$CY$4:$DC$523,2,FALSE) -> #N/A | DL4: 1 | DM4: DRN80M4 | DN4: 1751 | DP4: 2" SCH 40 | DQ4: 2.375 | DR4: 2.067 | DU4: 304 SS | DV4: 29000000 | DW4: 30000 | DX4: 75000 | DY4: 0.29 | EC4: 4 | ED4: =EC4&"S" -> 4S | EE4: 5 | EF4: 4.5 | EG4: 3.75 | EH4: =EC4&"R" -> 4R | EI4: 5 | EK4: 6 | EL4: 10 ft | EO4: Direct Coupled In-line | EP4: 0.95 | ES4: Wet Sludge | ET4: 0.75
A5: 6Dual | H5: =6*2.5 -> 15 | I5: 1.5 | J5: None | L5: 7 | M5: =(C5+E5)/2 -> 0 | N5: =D5+F5 -> 0 | V5: Pitch | X5: CF1 | AA5: CF15_ | AB5: CF30_ | AC5: CF45_ | AF5: CF3 | AJ5: 6 | AK5: 18 | AM5: None | AN5: 1 | AP5: Wet Sludge | AQ5: 1.5 | AS5: Standard | AT5: 1 | AV5: None | AW5: 1 | AY5: 0 | AZ5: 1 | BA5: 1 | BB5: 1 | BC5: 1 | BD5: 1 | BF5: 1 | BG5: 0.375 | BI5: A307 | BJ5: 36000 | BK5: 6200 | BM5: 1018 CS | BN5: 58000 | BO5: 17400 | BQ5: Carbon Steel | BR5: 58000 | BU5: Carbon Steel | BV5: 6.33e-06 | BX5: 16 ga | BY5: 0.06 | CA5: Wet Sludge | CB5: 65 | CC5: 21 | CD5: Granular | CE5: Sluggish | CF5: Mild | CG5: -- | CH5: -- | CJ5: Very Fine | CK5: A | CL5: Very Free Flowing | CM5: 1 | CN5: Mild | CO5: 5 | CP5: Build Up / Harden | CQ5: F | CV5: K57 | CW5: 2 | CX5: K57_2 | CY5: K5714 | CZ5: 123.85 | DA5: 14 | DB5: 5310 | DC5: 1720 | DE5: 2 | DF5: =$DE$3&"_"&DE5 -> 0_2 | DG5: =VLOOKUP(DF5,$CX$4:$DC$523,4,FALSE) -> #N/A | DH5: =$DE$3&DG5 -> #N/A | DL5: 1.5 | DM5: DRN90S4 | DN5: 1767 | DP5: 2" SCH 80 | DQ5: 2.375 | DR5: 1.939 | DU5: 304L SS | DV5: 29000000 | DW5: 25000 | DX5: 70000 | DY5: 0.29 | EC5: 6 | ED5: =EC5&"S" -> 6S | EE5: 7 | EF5: 6 | EG5: 5 | EH5: =EC5&"R" -> 6R | EI5: 7 | EK5: 9 | EL5: 10 ft | EO5: Screw Conveyor Drive | EP5: 0.95 | ES5: Wet Sludge + Lime | ET5: 0.7
A6: 9Dual | B6: 1.5 | C6: 0.75 | D6: 2.5 | E6: 0.5 | F6: 1 | G6: =C6&""" x "&D6&""" / "&E6&""" X "&F6&"""" -> 0.75" x 2.5" / 0.5" X 1" | H6: 17.2 | I6: 2 | J6: None | K6: 1.5 | L6: 7 | M6: =(C6+E6)/2 -> 0.625 | N6: =D6+F6 -> 3.5 | V6: Full | W6: OD | X6: 1 | Z6: Shafted | AA6: 1 | AB6: 1 | AC6: 1 | AE6: None | AF6: 1 | AJ6: 9 | AK6: 31 | AM6: Ball | AN6: 1 | AP6: Wet Sludge + Lime | AQ6: 1.5 | AS6: Cut15 | AT6: 1.1 | AV6: 1 | AW6: 1.29 | AY6: 10 | AZ6: 0.9 | BA6: 1 | BB6: 1 | BC6: 0.9 | BD6: 1 | BF6: 1.5 | BG6: 0.5 | BI6: A325 | BJ6: 92000 | BK6: 15500 | BM6: 1045 CS | BN6: 70000 | BO6: 21000 | BQ6: 304 SS | BR6: 30000 | BU6: 304/316 SS | BV6: 9.6e-06 | BX6: 14 ga | BY6: 0.0751 | CA6: Wet Sludge + Lime | CB6: 75 | CC6: 32 | CD6: Granular | CE6: Sluggish | CF6: Moderate | CG6: Stickiness / Adhesive | CH6: -- | CJ6: Fine | CK6: B | CL6: Free Flowing | CM6: 2 | CN6: Moderate | CO6: 6 | CP6: Generate Static Electricity | CQ6: G | CV6: K57 | CW6: 3 | CX6: K57_3 | CY6: K5716 | CZ6: 108.29 | DA6: 16 | DB6: 5310 | DC6: 1720 | DE6: 3 | DF6: =$DE$3&"_"&DE6 -> 0_3 | DG6: =VLOOKUP(DF6,$CX$4:$DC$523,4,FALSE) -> #N/A | DH6: =$DE$3&DG6 -> #N/A | DL6: 2 | DM6: DRN90L4 | DN6: 1767 | DP6: 2.5" SCH 40 | DQ6: 2.875 | DR6: 2.469 | DU6: 316 SS | DV6: 29000000 | DW6: 30000 | DX6: 75000 | DY6: 0.29 | EC6: 9 | ED6: =EC6&"S" -> 9S | EE6: 10 | EF6: 8 | EG6: 7.125 | EH6: =EC6&"R" -> 9R | EI6: 10 | EK6: 10 | EL6: 10 ft | EO6: Shaft Mount Drive | EP6: 0.95 | ES6: Partially Dried Sludge/Paste | ET6: 0.6
A7: 10Dual | B7: 3.5 | C7: 0.75 | D7: 2.5 | E7: 0.5 | F7: 1 | G7: =C7&""" x "&D7&""" / "&E7&""" X "&F7&"""" -> 0.75" x 2.5" / 0.5" X 1" | H7: =10*2.5 -> 25 | I7: 2 | J7: None | K7: 3.5 | L7: 7.75 | M7: =(C7+E7)/2 -> 0.625 | N7: =D7+F7 -> 3.5 | V7: Short | W7: 2/3 OD | X7: 1.5 | Z7: Single Shaftless | AA7: 1 | AB7: 1 | AC7: 1 | AE7: 1 | AF7: 1.08 | AJ7: 10 | AK7: 37 | AM7: Babbit | AN7: 1.7 | AP7: Partially Dried Sludge/Paste | AQ7: 2 | AS7: Cut 30 | AT7: 1.15 | AV7: 2 | AW7: 1.58 | AY7: 15 | AZ7: 0.7 | BA7: 1 | BB7: 1 | BC7: 0.7 | BD7: 0.9 | BF7: 2 | BG7: 0.625 | BI7: 304 SS | BJ7: 30000 | BK7: 6000 | BM7: 4140 Alloy | BN7: 70000 | BO7: 21000 | BQ7: 316 SS | BR7: 30000 | BU7: 304 SS | BV7: 9.6e-06 | BX7: 12 ga | BY7: 0.105 | CA7: Partially Dried Sludge/Paste | CB7: 55 | CC7: 55 | CD7: Granular | CE7: Average | CF7: Mild | CG7: Stickiness / Adhesive | CH7: -- | CJ7: Granular | CK7: C | CL7: Average | CM7: 3 | CN7: Extreme | CO7: 7 | CP7: Decomposes in Storage | CQ7: H | CV7: K57 | CW7: 4 | CX7: K57_4 | CY7: K5717 | CZ7: 102.88 | DA7: 17 | DB7: 5310 | DC7: 1720 | DE7: 4 | DF7: =$DE$3&"_"&DE7 -> 0_4 | DG7: =VLOOKUP(DF7,$CX$4:$DC$523,4,FALSE) -> #N/A | DH7: =$DE$3&DG7 -> #N/A | DL7: 3 | DM7: DRN100LM4 | DN7: 1762 | DP7: 2.5" SCH 80 | DQ7: 2.875 | DR7: 2.323 | DU7: 316L SS | DV7: 29000000 | DW7: 25000 | DX7: 70000 | DY7: 0.29 | EC7: 10 | ED7: =EC7&"S" -> 10S | EE7: 11 | EF7: 9 | EG7: 7.875 | EH7: =EC7&"R" -> 10R | EI7: 11 | EK7: 12 | EL7: 12 ft | EO7: Gearbox with Chain & Sprocket | EP7: =ROUND(0.95*0.93,2) -> 0.88 | ES7: Dry Biosolids | ET7: 0.45 | FJ7: If not supplied by the customer, use standard values.
A8: 12Dual | B8: 2 | C8: 1 | D8: 3 | E8: 0.75 | F8: 1.75 | G8: =C8&""" x "&D8&""" / "&E8&""" X "&F8&"""" -> 1" x 3" / 0.75" X 1.75" | H8: 31 | I8: 2.4375 | J8: None | K8: 2 | L8: 8.5 | M8: =(C8+E8)/2 -> 0.875 | N8: =D8+F8 -> 4.75 | V8: Half | W8: 1/2 OD | X8: 2 | Z8: Dual Shaftless | AA8: 1 | AB8: 1 | AC8: 1 | AE8: 2 | AF8: 1.16 | AJ8: 12 | AK8: 55 | AM8: Bronze | AN8: 1.7 | AP8: Dry Biosolids | AQ8: 2.6 | AS8: Cut45 | AT8: 1.2 | AV8: 3 | AW8: 1.87 | AY8: 20 | AZ8: 0.55 | BA8: 1 | BB8: 1 | BC8: 0.55 | BD8: 0.8 | BF8: 2.4375 | BG8: 0.625 | BI8: 316 SS | BJ8: 30000 | BK8: 6000 | BM8: 4140 Hardened | BN8: 125000 | BO8: 37500 | BQ8: Alloy 8620 | BR8: 80000 | BU8: 316 SS | BV8: 9.6e-06 | BX8: 10 ga | BY8: 0.135 | CA8: Dry Biosolids | CB8: 45 | CC8: 94 | CD8: Fine | CE8: Free Flowing | CF8: Moderate | CG8: -- | CH8: -- | CJ8: Lumpy | CK8: D | CL8: Sluggish | CM8: 4 | CP8: Flammability | CQ8: J | CV8: K57 | CW8: 5 | CX8: K57_5 | CY8: K5719 | CZ8: 90.26 | DA8: 19 | DB8: 5310 | DC8: 1720 | DE8: 5 | DF8: =$DE$3&"_"&DE8 -> 0_5 | DG8: =VLOOKUP(DF8,$CX$4:$DC$523,4,FALSE) -> #N/A | DH8: =$DE$3&DG8 -> #N/A | DL8: 5 | DM8: DRN100L4 | DN8: 1763 | DP8: 3" SCH 40 | DQ8: 3.5 | DR8: 3.068 | DU8: 17-4 PH -A | DV8: 28500000 | DW8: 115000 | DX8: 160000 | DY8: 0.28 | EC8: 12 | ED8: =EC8&"S" -> 12S | EE8: 13 | EF8: 10.5 | EG8: 8.875 | EH8: =EC8&"R" -> 12R | EI8: 13 | EK8: 14 | EL8: 12 ft | EO8: Gearbox with Belt & Sheave | EP8: =ROUND(0.95*0.94,2) -> 0.89 | ES8: Raw Screenings | ET8: 0.65
A9: 14Dual | B9: 2.5 | C9: 1 | D9: 3 | E9: 0.75 | F9: 2.5 | G9: =C9&""" x "&D9&""" / "&E9&""" X "&F9&"""" -> 1" x 3" / 0.75" X 2.5" | H9: 35.7 | I9: 2.938 | J9: None | K9: 2.5 | L9: 10.5 | M9: =(C9+E9)/2 -> 0.875 | N9: =D9+F9 -> 5.5 | V9: Long | W9: 3/2 OD | X9: 0.67 | Z9: Cut | AA9: 1.95 | AB9: 1.57 | AC9: 1.43 | AE9: 3 | AF9: 1.24 | AJ9: 14 | AK9: 78 | AM9: Bronze with Graphite | AN9: 1.7 | AP9: Raw Screenings | AQ9: 2 | AS9: Cut95 | AT9: 1.3 | AV9: 4 | AW9: 2.16 | AY9: 25 | AZ9: 0.42 | BA9: 0.87 | BB9: 1 | BC9: 0.42 | BD9: 0.7 | BF9: 3 | BG9: 0.75 | BM9: 304 SS | BN9: 30000 | BO9: 9000 | BQ9: T1 | BR9: 100000 | BU9: A53-77a | BV9: 6.33e-06 | BX9: 1/8 | BY9: =1/8 -> 0.125 | CA9: Raw Screenings | CB9: 65 | CC9: 18 | CD9: Irregular | CE9: Sluggish | CF9: Moderate | CG9: Build Up / Harden | CH9: Corrosive Gas Present | CJ9: Irregular | CK9: E | CP9: Becomes Plastic / Softens | CQ9: K | CV9: K57 | CW9: 6 | CX9: K57_6 | CY9: K5723 | CZ9: 76.56 | DA9: 23 | DB9: 5310 | DC9: 1720 | DE9: 6 | DF9: =$DE$3&"_"&DE9 -> 0_6 | DG9: =VLOOKUP(DF9,$CX$4:$DC$523,4,FALSE) -> #N/A | DH9: =$DE$3&DG9 -> #N/A | DL9: 7.5 | DM9: DRN132S4 | DN9: 1768 | DP9: 3" SCH 80 | DQ9: 3.5 | DR9: 2.9 | DU9: 17-4 PH -H900 | DV9: 28500000 | DW9: 185000 | DX9: 200000 | DY9: 0.282 | EC9: 14 | ED9: =EC9&"S" -> 14S | EE9: 15 | EF9: 11.5 | EG9: 10.125 | EH9: =EC9&"R" -> 14R | EI9: 15 | EK9: 16 | EL9: 12 ft | EO9: Open Spur Gear | EP9: =ROUND(0.95*0.9,2) -> 0.86 | ES9: Compacted Screenings | ET9: 0.65 | FJ9: Dewatered sludge 55-70 lb/ft3
A10: 16Dual | B10: 4.5 | C10: 1 | D10: 3 | E10: 0.75 | F10: 2.5 | G10: =C10&""" x "&D10&""" / "&E10&""" X "&F10&"""" -> 1" x 3" / 0.75" X 2.5" | H10: 39.2 | I10: 2.938 | J10: None | K10: 4.5 | L10: 12.5 | M10: =(C10+E10)/2 -> 0.875 | N10: =D10+F10 -> 5.5 | Z10: Cut & Folded | AA10: 1 | AB10: 3.75 | AC10: 2.54 | AE10: 4 | AF10: 1.32 | AJ10: 16 | AK10: 106 | AM10: Ceramic | AP10: Compacted Screenings | AQ10: 1.5 | AS10: Fold15 | AT10: 0 | AY10: 30 | AZ10: 0.3 | BA10: 0.67 | BB10: 0.8 | BC10: 0.3 | BD10: 0.6 | BF10: 3.4375 | BG10: 0.875 | BM10: 316 SS | BN10: 30000 | BO10: 9000 | BQ10: AR400 | BR10: 40000 | BU10: T1 | BV10: 7.2e-06 | BX10: 3/16 | BY10: =3/16 -> 0.1875 | CA10: Compacted Screenings | CB10: 75 | CC10: 38 | CD10: Irregular | CE10: Sluggish | CF10: Moderate | CG10: Build Up / Harden | CH10: Corrosive Gas Present | CP10: Very Dusty | CQ10: L | CV10: K57 | CW10: 7 | CX10: K57_7 | CY10: K5725 | CZ10: 69.12 | DA10: 25 | DB10: 5310 | DC10: 1720 | DE10: 7 | DF10: =$DE$3&"_"&DE10 -> 0_7 | DG10: =VLOOKUP(DF10,$CX$4:$DC$523,4,FALSE) -> #N/A | DH10: =$DE$3&DG10 -> #N/A | DL10: 10 | DM10: DRN132M4 | DN10: 1774 | DP10: 3.5" SCH 40 | DQ10: 4 | DR10: 3.548 | DU10: 17-4 PH -H1150 | DV10: 28500000 | DW10: 130000 | DX10: 150000 | DY10: 0.284 | EC10: 16 | ED10: =EC10&"S" -> 16S | EE10: 17 | EF10: 13.5 | EG10: 11.125 | EH10: =EC10&"R" -> 16R | EI10: 17 | EK10: 18 | EL10: 12 ft | ES10: Submerged Grit | ET10: 0.6 | FJ10: Partially dried sludge/paste 45-60 lb/ft3
A11: 18Dual | B11: 3.5 | C11: 1 | D11: 4 | E11: 0.75 | F11: 3 | G11: =C11&""" x "&D11&""" / "&E11&""" X "&F11&"""" -> 1" x 4" / 0.75" X 3" | H11: 45.4 | I11: 2.938 | J11: None | K11: 3.5 | L11: 14.5 | M11: =(C11+E11)/2 -> 0.875 | N11: =D11+F11 -> 7 | Z11: Ribbon | AA11: 1.04 | AB11: 1.37 | AC11: 1.62 | AJ11: 18 | AK11: 135 | AM11: Graphite | AP11: Submerged Grit | AQ11: 1.5 | AS11: Fold30 | AT11: 1.5 | AY11: 35 | AZ11: 0.22 | BA11: 0.5 | BB11: 0.65 | BC11: 0.22 | BD11: 0.54 | BF11: 4 | BG11: 0.875 | BM11: 17-4PH -A | BN11: 115000 | BO11: 34500 | BU11: AR400 | BV11: 3.6e-06 | BX11: 1/4 | BY11: =1/4 -> 0.25 | CA11: Submerged Grit | CB11: 100 | CC11: 5 | CD11: Granular | CE11: Free Flowing | CF11: Extreme | CG11: -- | CH11: -- | CP11: Aerates / Becomes Fluid | CQ11: M | CV11: K57 | CW11: 8 | CX11: K57_8 | CY11: K5729 | CZ11: 60.81 | DA11: 29 | DB11: 5310 | DC11: 1720 | DE11: 8 | DF11: =$DE$3&"_"&DE11 -> 0_8 | DG11: =VLOOKUP(DF11,$CX$4:$DC$523,4,FALSE) -> #N/A | DH11: =$DE$3&DG11 -> #N/A | DL11: 12.5 | DM11: DRN132L4 | DN11: 1775 | DP11: 3.5" SCH 80 | DQ11: 4 | DR11: 3.364 | DU11: CARBON STEEL | DV11: 28000000 | DW11: 80000 | DY11: 0.283 | EC11: 18 | ED11: =EC11&"S" -> 18S | EE11: 19 | EF11: 14.5 | EG11: 12.375 | EH11: =EC11&"R" -> 18R | EI11: 19 | EK11: 20 | EL11: 12 ft | ES11: Dewatered Grit | ET11: 0.65 | FJ11: Dry biosolids 25-45 lb/ft3
A12: 20Dual | B12: 5.5 | C12: 1 | D12: 4 | E12: 0.75 | F12: 3 | G12: =C12&""" x "&D12&""" / "&E12&""" X "&F12&"""" -> 1" x 4" / 0.75" X 3" | H12: 48.6 | I12: 3.4375 | J12: None | K12: 5.5 | L12: 16.5 | M12: =(C12+E12)/2 -> 0.875 | N12: =D12+F12 -> 7 | Z12: Paddle 1x | AA12: 1 | AB12: 1 | AC12: 1 | AJ12: 20 | AK12: 165 | AM12: Hard Iron | AN12: 4.4 | AP12: Dewatered Grit | AQ12: 2.6 | AS12: Fold45 | AT12: 1.7 | AY12: 40 | AZ12: 0.15 | BA12: 0.37 | BB12: 0.48 | BC12: 0.15 | BD12: 0.5 | BM12: 17-4PH -H900 | BN12: 185000 | BO12: 55500 | BX12: 3/8 | BY12: =3/8 -> 0.375 | CA12: Dewatered Grit | CB12: 120 | CC12: 20 | CD12: Granular | CE12: Sluggish | CF12: Extreme | CG12: -- | CH12: -- | CP12: Explosiveness | CQ12: N | CV12: K57 | CW12: 9 | CX12: K57_9 | CY12: K5730 | CZ12: 57.42 | DA12: 30 | DB12: 5310 | DC12: 1720 | DE12: 9 | DF12: =$DE$3&"_"&DE12 -> 0_9 | DG12: =VLOOKUP(DF12,$CX$4:$DC$523,4,FALSE) -> #N/A | DH12: =$DE$3&DG12 -> #N/A | DL12: 15 | DM12: DRN160M4 | DN12: 1776 | DP12: 4" SCH 40 | DQ12: 4.5 | DR12: 4.026 | DU12: Alloy 8620 | DV12: 28000000 | DW12: 80000 | DY12: 0.283 | EC12: 20 | ED12: =EC12&"S" -> 20S | EE12: 21 | EF12: 15.5 | EG12: 13.375 | EH12: =EC12&"R" -> 20R | EI12: 21 | EK12: 24 | EL12: 12 ft | ES12: Lime Pebble | ET12: 0.55 | FJ12: Raw screenings 35-65 lb/ft3
A13: 24Dual | B13: 9.5 | C13: 1 | D13: 4 | E13: 0.75 | F13: 3 | G13: =C13&""" x "&D13&""" / "&E13&""" X "&F13&"""" -> 1" x 4" / 0.75" X 3" | H13: 53.6 | I13: 3.4375 | J13: None | K13: 9.5 | L13: 20.5 | M13: =(C13+E13)/2 -> 0.875 | N13: =D13+F13 -> 7 | Z13: Paddle 2x | AA13: 1 | AB13: 1 | AC13: 1 | AJ13: 24 | AK13: 235 | AM13: Stellite | AN13: 4.4 | AP13: Lime Pebble | AQ13: 2 | AS13: Fold95 | AT13: 2.3 | AY13: 45 | AZ13: 0.1 | BA13: 0.28 | BB13: 0.36 | BC13: 0.1 | BD13: 0.5 | BM13: 17-4PH -H1150 | BN13: 130000 | BO13: 39000 | CA13: Lime Pebble | CB13: 45 | CC13: 94 | CD13: Granular | CE13: Average | CF13: Moderate | CG13: Very Dusty | CH13: -- | CP13: Stickiness / Adhesive | CQ13: O | CV13: K57 | CW13: 10 | CX13: K57_10 | CY13: K5736 | CZ13: 48.89 | DA13: 36 | DB13: 5310 | DC13: 1720 | DE13: 10 | DF13: =$DE$3&"_"&DE13 -> 0_10 | DG13: =VLOOKUP(DF13,$CX$4:$DC$523,4,FALSE) -> #N/A | DH13: =$DE$3&DG13 -> #N/A | DL13: 20 | DM13: DRN160L4 | DN13: 1777 | DP13: 4" SCH 80 | DQ13: 4.5 | DR13: 3.826 | DU13: 1045 CS | DV13: 28000000 | DW13: 70000 | DY13: 0.283 | EC13: 24 | ED13: =EC13&"S" -> 24S | EE13: 25 | EF13: 17.5 | EG13: 15.375 | EH13: =EC13&"R" -> 24R | EI13: 25 | ES13: Lime Powder/Hydrated | ET13: 0.55 | FJ13: Compacted screenings 55-75 lb/ft3
A14: 6Single | H14: =6*1.8 -> 10.8 | I14: 1.5 | J14: None | L14: 7 | M14: =(C14+E14)/2 -> 0 | N14: =D14+F14 -> 0 | Z14: Paddle 3x | AA14: 1 | AB14: 1 | AC14: 1 | AM14: Plastech | AN14: 2 | AP14: Lime Powder/Hydrated | AQ14: 2 | AS14: Ribbon15 | AT14: 1 | CA14: Lime Powder/Hydrated | CB14: 45 | CC14: 94 | CD14: Fine | CE14: Free Flowing | CF14: Moderate | CG14: Very Dusty | CP14: Harmful / Toxic Gas or Fumes | CQ14: R | CV14: K57 | CW14: 11 | CX14: K57_11 | CY14: K5739 | CZ14: 44.43 | DA14: 39 | DB14: 5310 | DC14: 1720 | DE14: 11 | DF14: =$DE$3&"_"&DE14 -> 0_11 | DG14: =VLOOKUP(DF14,$CX$4:$DC$523,4,FALSE) -> #N/A | DH14: =$DE$3&DG14 -> #N/A | DL14: 25 | DM14: DRN180M4 | DN14: 1781 | DP14: 5" SCH 40 | DQ14: 5.563 | DR14: 5.047 | DU14: T1 | DV14: 27000000 | DW14: 100000 | DY14: 0.283 | FJ14: Submerged grit 65-110 lb/ft3
A15: 9Single | B15: 3.5 | C15: 0.75 | D15: 2.5 | E15: 0 | F15: 0 | G15: =C15&""" x "&D15&"""" -> 0.75" x 2.5" | H15: 13.6 | I15: 2 | J15: None | K15: 3.5 | L15: 7 | M15: =(C15+E15) -> 0.75 | N15: =D15+F15 -> 2.5 | Z15: Paddle 4x | AA15: 1 | AB15: 1 | AC15: 1 | AM15: Nylon | AN15: 2 | AP15: Other | AQ15: 1.5 | AS15: Ribbon30 | AT15: 1.14 | CA15: Other | CB15: 65 | CC15: 20 | CD15: Granular | CE15: Average | CP15: Highly Corrosive | CQ15: S | CV15: K57 | CW15: 12 | CX15: K57_12 | CY15: K5745 | CZ15: 38.49 | DA15: 45 | DB15: 5310 | DC15: 1680 | DE15: 12 | DF15: =$DE$3&"_"&DE15 -> 0_12 | DG15: =VLOOKUP(DF15,$CX$4:$DC$523,4,FALSE) -> #N/A | DH15: =$DE$3&DG15 -> #N/A | DL15: 30 | DM15: DRN180L4 | DN15: 1781 | DP15: 5" SCH 80 | DQ15: 5.563 | DR15: 4.813 | DU15: 1018 CS | DV15: 28000000 | DW15: 80000 | DY15: 0.283 | FJ15: Dewatered
A16: 10Single | B16: 5.5 | C16: 0.75 | D16: 2.5 | E16: 0 | F16: 0 | G16: =C16&""" x "&D16&"""" -> 0.75" x 2.5" | H16: =10*1.8 -> 18 | I16: 2 | J16: None | K16: 5.5 | L16: 7.75 | M16: =(C16+E16) -> 0.75 | N16: =D16+F16 -> 2.5 | AM16: Teflon | AN16: 2 | AS16: Ribbon45 | AT16: 1.2 | BM16: conservative working allowable of about 30% of yield strength for keyed shafts/general equipment design. ASME-style shaft guidance commonly uses 30% of yield, with a further reduction for keyways; pure shear yield by von Mises is about 57.7% of yield, so 30% Fy already includes a practical safety margin. | CP16: Mildly Corrosive | CQ16: T | CV16: K57 | CW16: 13 | CX16: K57_13 | CY16: K5749 | CZ16: 35.7 | DA16: 49 | DB16: 5310 | DC16: 1620 | DE16: 13 | DF16: =$DE$3&"_"&DE16 -> 0_13 | DG16: =VLOOKUP(DF16,$CX$4:$DC$523,4,FALSE) -> #N/A | DH16: =$DE$3&DG16 -> #N/A | DP16: 6" SCH 40 | DQ16: 6.625 | DR16: 6.065 | DU16: 4140 Hardened | DV16: 28000000 | DW16: 125000 | DX16: 140000 | DY16: 0.283
A17: 12Single | B17: 5.5 | C17: 1 | D17: 3 | E17: 0 | F17: 0 | G17: =C17&""" x "&D17&"""" -> 1" x 3" | H17: 24.4 | I17: 2.4375 | J17: None | K17: 5.5 | L17: 8.5 | M17: =(C17+E17) -> 1 | N17: =D17+F17 -> 3 | AM17: UHMW | AN17: 2 | AS17: Ribbon95 | AT17: 1 | CP17: Packs Under Pressure | CQ17: X | CV17: K57 | CW17: 14 | CX17: K57_14 | CY17: K5758 | CZ17: 30.28 | DA17: 58 | DB17: 5310 | DC17: 1480 | DE17: 14 | DF17: =$DE$3&"_"&DE17 -> 0_14 | DG17: =VLOOKUP(DF17,$CX$4:$DC$523,4,FALSE) -> #N/A | DH17: =$DE$3&DG17 -> #N/A | DP17: 6" SCH 80 | DQ17: 6.625 | DR17: 5.761 | DU17: AR400 | DV17: 29000000 | DW17: 40000 | DY17: 0.283
A18: 14Single | B18: 7.5 | C18: 1 | D18: 3 | E18: 0 | F18: 0 | G18: =C18&""" x "&D18&"""" -> 1" x 3" | H18: 26.4 | I18: 2.938 | J18: None | K18: 7.5 | L18: 10.5 | M18: =(C18+E18) -> 1 | N18: =D18+F18 -> 3 | CP18: Elevated Temperature | CQ18: Z | CV18: K57 | CW18: 15 | CX18: K57_15 | CY18: K5764 | CZ18: 27.34 | DA18: 64 | DB18: 5310 | DC18: 1400 | DE18: 15 | DF18: =$DE$3&"_"&DE18 -> 0_15 | DG18: =VLOOKUP(DF18,$CX$4:$DC$523,4,FALSE) -> #N/A | DH18: =$DE$3&DG18 -> #N/A | DP18: 8" SCH 40 | DQ18: 8.625 | DR18: 7.981
A19: 16Single | B19: 9.5 | C19: 1 | D19: 3 | E19: 0 | F19: 0 | G19: =C19&""" x "&D19&"""" -> 1" x 3" | H19: 27.9 | I19: 2.938 | J19: None | K19: 9.5 | L19: 12.5 | M19: =(C19+E19) -> 1 | N19: =D19+F19 -> 3 | CV19: K67R37 | CW19: 1 | CX19: K67R37_1 | CY19: K67R372.2 | CZ19: 793 | DA19: 2.2 | DB19: 7260 | DC19: 2320 | DP19: 8" SCH 80 | DQ19: 8.625 | DR19: 7.625
A20: 18Single | B20: 9.5 | C20: 1 | D20: 4 | E20: 0 | F20: 0 | G20: =C20&""" x "&D20&"""" -> 1" x 4" | H20: 33.8 | I20: 2.938 | J20: None | K20: 9.5 | L20: 14.5 | M20: =(C20+E20) -> 1 | N20: =D20+F20 -> 4 | CV20: K67R37 | CW20: 2 | CX20: K67R37_2 | CY20: K67R372.5 | CZ20: 697 | DA20: 2.5 | DB20: 7260 | DC20: 2320 | DP20: 10" SCH 40 | DQ20: 10.75 | DR20: 10.02
A21: 20Single | B21: 11.5 | C21: 1 | D21: 4 | E21: 0 | F21: 0 | G21: =C21&""" x "&D21&"""" -> 1" x 4" | H21: 35.5 | I21: 3.4375 | J21: None | K21: 11.5 | L21: 16.5 | M21: =(C21+E21) -> 1 | N21: =D21+F21 -> 4 | CV21: K67R37 | CW21: 3 | CX21: K67R37_3 | CY21: K67R372.9 | CZ21: 613 | DA21: 2.9 | DB21: 7260 | DC21: 2320 | DP21: 10" SCH 60 | DQ21: 10.75 | DR21: 9.75
A22: 24Single | B22: 15.5 | C22: 1 | D22: 4 | E22: 0 | F22: 0 | G22: =C22&""" x "&D22&"""" -> 1" x 4" | H22: 38.1 | I22: 3.4375 | J22: None | K22: 15.5 | L22: 20.5 | M22: =(C22+E22) -> 1 | N22: =D22+F22 -> 4 | R22: old | CV22: K67R37 | CW22: 4 | CX22: K67R37_4 | CY22: K67R373.2 | CZ22: 542 | DA22: 3.2 | DB22: 7260 | DC22: 2320 | DP22: 12" SCH 40 | DQ22: 12.75 | DR22: 11.938
A23: 6Shafted1 | C23: 0.1875 | G23: =C23 -> 0.1875 | H23: 7.5 | I23: 1.5 | J23: 2" SCH 40 | R23: 2.375 | CV23: K67R37 | CW23: 5 | CX23: K67R37_5 | CY23: K67R373.7 | CZ23: 471 | DA23: 3.7 | DB23: 7260 | DC23: 2320 | DP23: 12" SCH 80 | DQ23: 12.75 | DR23: 11.374
A24: 9Shafted1 | C24: 0.1875 | G24: =C24 -> 0.1875 | H24: 9.5 | I24: 1.5 | J24: 2" SCH 40 | R24: 2.375 | CV24: K67R37 | CW24: 6 | CX24: K67R37_6 | CY24: K67R374.2 | CZ24: 420 | DA24: 4.2 | DB24: 7260 | DC24: 2320
A25: 10Shafted1 | C25: 0.1875 | G25: =C25 -> 0.1875 | H25: 12 | I25: 1.5 | J25: 2" SCH 40 | R25: 2.375 | CV25: K67R37 | CW25: 7 | CX25: K67R37_7 | CY25: K67R374.8 | CZ25: 361 | DA25: 4.8 | DB25: 7260 | DC25: 2320
A26: 12Shafted1 | C26: 0.1875 | G26: =C26 -> 0.1875 | H26: 13 | I26: 2 | J26: 2.5" SCH 40 | R26: 2.875 | CV26: K67R37 | CW26: 8 | CX26: K67R37_8 | CY26: K67R375.4 | CZ26: 323 | DA26: 5.4 | DB26: 7260 | DC26: 2320
A27: 14Shafted1 | C27: 0.1875 | G27: =C27 -> 0.1875 | H27: 18 | I27: 2.4375 | J27: 3" SCH 40 | R27: 3.5 | CV27: K67R37 | CW27: 9 | CX27: K67R37_9 | CY27: K67R376.3 | CZ27: 279 | DA27: 6.3 | DB27: 7260 | DC27: 2320
A28: 16Shafted1 | C28: 0.1875 | G28: =C28 -> 0.1875 | H28: 20 | I28: 2.938 | J28: 3.5" SCH 40 | R28: 4 | AI28: Drive Efficiency | CV28: K67R37 | CW28: 10 | CX28: K67R37_10 | CY28: K67R377.1 | CZ28: 246 | DA28: 7.1 | DB28: 7260 | DC28: 2320 | DW28: =VLOOKUP(J49,Reference!BM5:BO14,3,FALSE) -> #N/A
A29: 18Shafted1 | C29: 0.1875 | G29: =C29 -> 0.1875 | H29: 21 | I29: 2.938 | J29: 3.5" SCH 40 | R29: 4 | AJ29: ID | AK29: e | CV29: K67R37 | CW29: 11 | CX29: K67R37_11 | CY29: K67R378.1 | CZ29: 217 | DA29: 8.1 | DB29: 7260 | DC29: 2320
A30: 20Shafted1 | C30: 0.1875 | G30: =C30 -> 0.1875 | H30: 26 | I30: 2.938 | J30: 3.5" SCH 40 | R30: 4 | AI30: Direct Couplied In-line | AJ30: DC | AK30: 0.94 | CV30: K67R37 | CW30: 12 | CX30: K67R37_12 | CY30: K67R379.1 | CZ30: 191 | DA30: 9.1 | DB30: 7260 | DC30: 2320
A31: 24Shafted1 | C31: 0.25 | G31: =C31 -> 0.25 | H31: 37 | I31: 3.4375 | J31: 4" SCH 40 | R31: 4.5 | AI31: Screw Conveyor Drive | AJ31: SC | AK31: 0.88 | CV31: K67R37 | CW31: 13 | CX31: K67R37_13 | CY31: K67R3711 | CZ31: 166 | DA31: 11 | DB31: 7260 | DC31: 2320
A32: 6Shafted2 | C32: 0.25 | G32: =C32 -> 0.25 | H32: 8 | I32: 1.5 | J32: 2" SCH 40 | R32: 2.375 | AI32: Shaft Mount Drive | AJ32: SM | AK32: 0.88 | CV32: K67R37 | CW32: 14 | CX32: K67R37_14 | CY32: K67R3712 | CZ32: 144 | DA32: 12 | DB32: 7260 | DC32: 2320
A33: 9Shafted2 | C33: 0.25 | G33: =C33 -> 0.25 | H33: 13 | I33: 2 | J33: 2.5" SCH 40 | R33: 2.875 | AI33: Gearbox with Chain & Sprocket | AJ33: GR | AK33: 0.85 | CV33: K67R37 | CW33: 15 | CX33: K67R37_15 | CY33: K67R3714 | CZ33: 122 | DA33: 14 | DB33: 7260 | DC33: 2320
A34: 10Shafted2 | C34: 0.25 | G34: =C34 -> 0.25 | H34: 13.5 | I34: 2 | J34: 2.5" SCH 40 | R34: 2.875 | CV34: K77 | CW34: 1 | CX34: K77_1 | CY34: K779.1 | CZ34: 192.18 | DA34: 9.1 | DB34: 12800 | DC34: 3610
A35: 12Shafted2 | C35: 0.25 | G35: =C35 -> 0.25 | H35: 17 | I35: 2.4375 | J35: 3" SCH 40 | R35: 3.5 | CV35: K77 | CW35: 2 | CX35: K77_2 | CY35: K779.8 | CZ35: 179.37 | DA35: 9.8 | DB35: 12800 | DC35: 3610
A36: 14Shafted2 | C36: 0.25 | G36: =C36 -> 0.25 | H36: 20 | I36: 2.938 | J36: 3" SCH 40 | R36: 3.5 | CV36: K77 | CW36: 3 | CX36: K77_3 | CY36: K7711 | CZ36: 154.02 | DA36: 11 | DB36: 13700 | DC36: 3460
A37: 16Shafted2 | C37: 0.25 | G37: =C37 -> 0.25 | H37: 24 | I37: 2.938 | J37: 3.5" SCH 40 | R37: 4 | CV37: K77 | CW37: 4 | CX37: K77_4 | CY37: K7713 | CZ37: 135.28 | DA37: 13 | DB37: 13700 | DC37: 3460
A38: 18Shafted2 | C38: 0.25 | G38: =C38 -> 0.25 | H38: 25 | I38: 2.938 | J38: 3.5" SCH 40 | R38: 4 | CV38: K77 | CW38: 5 | CX38: K77_5 | CY38: K7714 | CZ38: 128.52 | DA38: 14 | DB38: 13700 | DC38: 3460
A39: 20Shafted2 | C39: 0.25 | G39: =C39 -> 0.25 | H39: 31 | I39: 3.4375 | J39: 3.5" SCH 40 | R39: 4 | CV39: K77 | CW39: 6 | CX39: K77_6 | CY39: K7715 | CZ39: 113.56 | DA39: 15 | DB39: 13700 | DC39: 3460
A40: 24Shafted2 | C40: 0.25 | G40: =C40 -> 0.25 | H40: 43 | I40: 3.4375 | J40: 4" SCH 40 | R40: 4.5 | CV40: K77 | CW40: 7 | CX40: K77_7 | CY40: K7718 | CZ40: 97.05 | DA40: 18 | DB40: 13700 | DC40: 3460
...

Sheet Revision
I1: Updates to research | L1: Status: N = not started, P = in progress, C = complete
A2: Latest: | B2: Revision | C2: Date | D2: By | E2: Description | H2: Number | I2: Description | J2: Date Added | K2: By | L2: Status | M2: Outcome
A3: =MAX(B3:B200) -> 21 | B3: 0 | C3: 44950 | D3: PTA | E3: Initial release, sections incomplete | H3: 1 | I3: Thermal expansion for shaftless screws | J3: 45310 | K3: PTA | L3: N
A4: =MAX(C3:C200) -> 46181 | B4: 1 | C4: 45034 | D4: KBA | E4: Lookup Equation for Incline Factor | H4: 2 | I4: Drawing notes as an output for designers | J4: 45310 | K4: PTA | L4: N
B5: 2 | C5: 45057 | D5: PTA | E5: Fixed decimal place in fill factor entry, added strength values for 4140 shaft material | H5: 3 | I5: Compare CEMA standard sizes to TCC standard sizes | J5: 45310
B6: 3 | C6: 45085 | D6: KBA | E6: Update list of shaft sizes, add 17-4PH to shaft allowable stress | H6: 4 | I6: Add option to include bolt pads in the bolted coupling calculation section | J6: 45310 | K6: PTA | L6: C | M6: Added in rev 17
B7: 4 | C7: 45091 | D7: KBA | E7: Update calculation of "Spiral Thickness Av" on Reference tab, column M for the single spirals (removed dividing by 2) | H7: 5 | I7: Add instrumentation to the component selection | J7: 45310 | K7: PTA | L7: C | M7: Added in rev 17
B8: 5 | C8: 45141 | D8: KBA | E8: Added seismic tab | H8: 6 | I8: Add hinged as option for cover hold down | J8: 45310 | K8: PTA | L8: C | M8: Added in rev 17
B9: 6 | C9: 45162 | D9: KBA | E9: Added 1/8" to Cover sizes [List > AJ]and updated 16 ga values [Reference > BX & BY]
B10: 7 | C10: 45176 | D10: KBA | E10: Added T1 Steel (ASTM A514 Grad B) to Reference Tab [Flight Yeld Stress, Coefficient of Thermal Expansion & Material Properties Table]
B11: 8 | C11: 45260 | D11: PTA | E11: Added 1018 CS to material tab in reference for shaft material property lookup
C12: 45260 | D12: PTA | E12: Changed lookup for shaftless screw ID to be based on the selected flight size rather than the standard ID based on screw size. (ref tab added column "id from flight", changed lookup in cell c3 to search based on this)
C13: 45260 | D13: PTA | E13: Removed drive drop down selections in design tab, added gearbox SF input
C14: 45260 | D14: PTA | E14: Fixed capacity calculation when using non-standard pitch screws. Pitch factor CF1 will no longer be used in the equivalent capacity calculation because the pitch is already factored into the capacity per revolution calculation.
C15: 45260 | D15: PTA | E15: Added check for max shaft size based on pipe ID for pin coupling connection
C16: 45260 | D16: PTA | E16: Removed option to select size for coupling pipe, which was already selected in earlier step for screw pipe size
C17: 45260 | D17: PTA | E17: Formatting updates, locked non-input cells on design sheet
C18: 45260 | D18: PTA | E18: Numerous updates to the datasheet
B19: 9 | C19: 45261 | D19: PTA | E19: Updated selection list for gearmotor shaft size.
C20: 45261 | D20: PTA | E20: Added check for coupling bolt being weakest link.
C21: 45261 | D21: PTA | E21: Changed screw length value for screw thermal expansion calculation to use length between bearings rather than full screw length.
C22: 45261 | D22: PTA | E22: Added some notes to cells for aid in performing calculations.
C23: 45261 | D23: PTA | E23: Changed list for drive arrangement, added lookup for efficiency from CEMA
B24: 10 | C24: 45296 | D24: PTA | E24: Updated error in incline factor lookup for angles less than 10 deg.
B25: 11 | C25: 45302 | D25: PTA | E25: Fixed typo in selection for drive arrangement
B26: 12 | C26: 45327 | D26: PTA | E26: Added hardened 4140 as shaft material option along with mechanical properties from TCC catalog.
B27: 13 | C27: 45330 | D27: PTA | E27: Fixed pipe size chart data on reference tab, some sizes were slightly off.
B28: 14 | C28: 45349 | D28: PTA | E28: Fixed spiral stress calculation to be based on selected spiral size rather than standard size.
B29: 15 | C29: 45351 | D29: KBA | E29: Add AR400 Steel as a selection for flight material
B30: 16 | C30: 45470 | D30: KBA | E30: Update drive shaft material list
B31: 17 | C31: 45482 | D31: PTA | E31: Added list of items to research for potential updates. List located on Revision tab.
C32: 45482 | D32: PTA | E32: Added check to gearbox shaft/bore size selection to highlight red if selected shaft/bore is more than 20% larger than the drive shaft.
C33: 45482 | D33: PTA | E33: Added bolt pad option to cross-bolt coupling calculation.
C34: 45482 | D34: PTA | E34: Added instrumentation to component selection table. Added hinged as option for cover hold downs.
C35: 45482 | D35: PTA | E35: Added more conveyance materials in selection table. Added default material characteristics for each option.
B36: 18 | C36: 45575 | D36: KBA | E36: Changed ID lookup
B37: 19 | C37: 45716 | D37: PTA | E37: Added material lift HP for incline screw HP calc per CEMA 350 ch 7.
B38: 20 | C38: 45888 | D38: PTA | E38: Fixed lookup for material factor table.
B39: 21 | C39: 46181 | D39: ACS | E39: Corrected shaft shear stress numbers
C40: 46181 | D40: ACS | E40: Changed Hanger Bearing selection to Hanger/Liner
...
